Workbook
Name IQ_CH: 110000
Name IQ_CQ: 5000
Name IQ_CY: 10000
Name IQ_DAILY: 500000
Name IQ_FH: 100000
Name IQ_FQ: 500
Name IQ_FY: 1000
Name IQ_LTM: 2000
Name IQ_MONTH: 15000
Name IQ_NTM: 6000
Name IQ_WEEK: 50000
Name IQ_YTD: 3000
Name UPDATE: '[1]Data Sheet'!$E$1
Name UPDATE: 'Data Sheet'!$E$1

Sheet Dupont Analysis>

Sheet Dupont Analysis
B3: ='Data Sheet'!B1 -> ASIAN PAINTS LTD
B4: =CONCATENATE(" ","(",VLOOKUP(B3,'List of Stocks'!A2:C5442,3,1)," | ","BSE Code: ",VLOOKUP(B3,'List of Stocks'!A2:B5442,2,1),")") -> (ASIANPAINT | BSE Code: 500820)
B5: =CONCATENATE(" ","INR "&'Data Sheet'!B8) -> INR 2519
B6: 52 Week (High - INR 3394.90 & Low - 2124.75)
B8: About the company
B9: Asian Paints Ltd is an Indian multinational paint company, headquartered in Mumbai. The company is engaged in the business of manufacturing, selling and distribution of paints, coatings, products related to home décor, bath fittings and providing related services. Asian Paints is India's largest paints company by market share. The company has 27 paint manufacturing facilities in 15 countries, servicing consumers in over 60 countries. Asian Paints is also present in the home improvement and décor space in India.
B14: Financial Summary
B60: Return on Equity (ROE)
C61: =HistoricalFS!F3 -> 43555 | D61: =HistoricalFS!G3 -> 43921 | E61: =HistoricalFS!H3 -> 44286 | F61: =HistoricalFS!I3 -> 44651 | G61: =HistoricalFS!J3 -> 45016 | H61: =HistoricalFS!K3 -> 45382 | I61: =HistoricalFS!L3 -> 45747
B62: Net Profit | C62: =HistoricalFS!F33 -> 2520.79 | D62: =HistoricalFS!G33 -> 2897.44 | E62: =HistoricalFS!H33 -> 3060 | F62: =HistoricalFS!I33 -> 5438.87 | G62: =HistoricalFS!J33 -> 4383.33 | H62: =HistoricalFS!K33 -> 4009.13 | I62: =HistoricalFS!L33 -> 3769.49
B63: Average Shareholder Equity | C63: =(SUM('Data Sheet'!E57:E58)+SUM('Data Sheet'!D57:D58))/2 -> 8940.39 | D63: =(SUM('Data Sheet'!F57:F58)+SUM('Data Sheet'!E57:E58))/2 -> 9800.355 | E63: =(SUM('Data Sheet'!G57:G58)+SUM('Data Sheet'!F57:F58))/2 -> 11468.225 | F63: =(SUM('Data Sheet'!H57:H58)+SUM('Data Sheet'!G57:G58))/2 -> 13308.925 | G63: =(SUM('Data Sheet'!I57:I58)+SUM('Data Sheet'!H57:H58))/2 -> 14901.895 | H63: =(SUM('Data Sheet'!J57:J58)+SUM('Data Sheet'!I57:I58))/2 -> 17360.265 | I63: =(SUM('Data Sheet'!K57:K58)+SUM('Data Sheet'!J57:J58))/2 -> 19064.055
B64: Return on Equity | C64: =C62/C63 -> 0.28195526 | D64: =D62/D63 -> 0.29564643 | E64: =E62/E63 -> 0.2668242 | F64: =F62/F63 -> 0.40866336 | G64: =G62/G63 -> 0.29414581 | H64: =H62/H63 -> 0.23093714 | I64: =I62/I63 -> 0.19772761
B66: ROE - Dupont Equation
C67: =C61 -> 43555 | D67: =D61 -> 43921 | E67: =E61 -> 44286 | F67: =F61 -> 44651 | G67: =G61 -> 45016 | H67: =H61 -> 45382 | I67: =I61 -> 45747
B68: =B62 -> Net Profit | C68: =C62 -> 2520.79 | D68: =D62 -> 2897.44 | E68: =E62 -> 3060 | F68: =F62 -> 5438.87 | G68: =G62 -> 4383.33 | H68: =H62 -> 4009.13 | I68: =I62 -> 3769.49
B69: Revenue | C69: =HistoricalFS!F6 -> 19240.13 | D69: =HistoricalFS!G6 -> 20211.25 | E69: =HistoricalFS!H6 -> 21712.79 | F69: =HistoricalFS!I6 -> 29101.28 | G69: =HistoricalFS!J6 -> 34488.59 | H69: =HistoricalFS!K6 -> 35494.73 | I69: =HistoricalFS!L6 -> 33905.62
B70: Net Profit Margin (A) | C70: =C68/C69 -> 0.13101731 | D70: =D68/D69 -> 0.14335778 | E70: =E68/E69 -> 0.14093076 | F70: =F68/F69 -> 0.18689453 | G70: =G68/G69 -> 0.12709508 | H70: =H68/H69 -> 0.11295001 | I70: =I68/I69 -> 0.11117596
B72: Revenue | C72: =C69 -> 19240.13 | D72: =D69 -> 20211.25 | E72: =E69 -> 21712.79 | F72: =F69 -> 29101.28 | G72: =G69 -> 34488.59 | H72: =H69 -> 35494.73 | I72: =I69 -> 33905.62
B73: Average Total Asset | C73: =('Data Sheet'!E66+'Data Sheet'!D66)/2 -> 15006.16 | D73: =('Data Sheet'!F66+'Data Sheet'!E66)/2 -> 16193.405 | E73: =('Data Sheet'!G66+'Data Sheet'!F66)/2 -> 18246.655 | F73: =('Data Sheet'!H66+'Data Sheet'!G66)/2 -> 21656.885 | G73: =('Data Sheet'!I66+'Data Sheet'!H66)/2 -> 24368.88 | H73: =('Data Sheet'!J66+'Data Sheet'!I66)/2 -> 27840.05 | I73: =('Data Sheet'!K66+'Data Sheet'!J66)/2 -> 30128.01
B74: Asset Turnover Ratio (B) | C74: =C72/C73 -> 1.2821488 | D74: =D72/D73 -> 1.2481161 | E74: =E72/E73 -> 1.18996 | F74: =F72/F73 -> 1.3437426 | G74: =G72/G73 -> 1.4152719 | H74: =H72/H73 -> 1.2749521 | I74: =I72/I73 -> 1.1253853
B76: =B73 -> Average Total Asset | C76: =C73 -> 15006.16 | D76: =D73 -> 16193.405 | E76: =E73 -> 18246.655 | F76: =F73 -> 21656.885 | G76: =G73 -> 24368.88 | H76: =H73 -> 27840.05 | I76: =I73 -> 30128.01
B77: =B63 -> Average Shareholder Equity | C77: =C63 -> 8940.39 | D77: =D63 -> 9800.355 | E77: =E63 -> 11468.225 | F77: =F63 -> 13308.925 | G77: =G63 -> 14901.895 | H77: =H63 -> 17360.265 | I77: =I63 -> 19064.055
B78: Equity Multiplier (C) | C78: =C76/C77 -> 1.6784682 | D78: =D76/D77 -> 1.6523284 | E78: =E76/E77 -> 1.5910618 | F78: =F76/F77 -> 1.6272453 | G78: =G76/G77 -> 1.6352873 | H78: =H76/H77 -> 1.603665 | I78: =I76/I77 -> 1.5803569
B80: Return on Equity (A*B*C) | C80: =C78*C74*C70 -> 0.28195526 | D80: =D78*D74*D70 -> 0.29564643 | E80: =E78*E74*E70 -> 0.2668242 | F80: =F78*F74*F70 -> 0.40866336 | G80: =G78*G74*G70 -> 0.29414581 | H80: =H78*H74*H70 -> 0.23093714 | I80: =I78*I74*I70 -> 0.19772761
B82: Return on Asset
C83: =C67 -> 43555 | D83: =D67 -> 43921 | E83: =E67 -> 44286 | F83: =F67 -> 44651 | G83: =G67 -> 45016 | H83: =H67 -> 45382 | I83: =I67 -> 45747
B84: Net Profit | C84: =C68 -> 2520.79 | D84: =D68 -> 2897.44 | E84: =E68 -> 3060 | F84: =F68 -> 5438.87 | G84: =G68 -> 4383.33 | H84: =H68 -> 4009.13 | I84: =I68 -> 3769.49
B85: =B76 -> Average Total Asset | C85: =C73 -> 15006.16 | D85: =D73 -> 16193.405 | E85: =E73 -> 18246.655 | F85: =F73 -> 21656.885 | G85: =G73 -> 24368.88 | H85: =H73 -> 27840.05 | I85: =I73 -> 30128.01
B86: Return on Asset | C86: =C84/C85 -> 0.16798368 | D86: =D84/D85 -> 0.17892716 | E86: =E84/E85 -> 0.16770197 | F86: =F84/F85 -> 0.25113815 | G86: =G84/G85 -> 0.17987409 | H86: =H84/H85 -> 0.14400585 | I86: =I84/I85 -> 0.1251158
B88: ROA - Dupont Equation
C89: =C83 -> 43555 | D89: =D83 -> 43921 | E89: =E83 -> 44286 | F89: =F83 -> 44651 | G89: =G83 -> 45016 | H89: =H83 -> 45382 | I89: =I83 -> 45747
B90: =B84 -> Net Profit | C90: =C84 -> 2520.79 | D90: =D84 -> 2897.44 | E90: =E84 -> 3060 | F90: =F84 -> 5438.87 | G90: =G84 -> 4383.33 | H90: =H84 -> 4009.13 | I90: =I84 -> 3769.49
B91: Revenue | C91: =C72 -> 19240.13 | D91: =D72 -> 20211.25 | E91: =E72 -> 21712.79 | F91: =F72 -> 29101.28 | G91: =G72 -> 34488.59 | H91: =H72 -> 35494.73 | I91: =I72 -> 33905.62
B92: Net Profit Margin (A) | C92: =C90/C91 -> 0.13101731 | D92: =D90/D91 -> 0.14335778 | E92: =E90/E91 -> 0.14093076 | F92: =F90/F91 -> 0.18689453 | G92: =G90/G91 -> 0.12709508 | H92: =H90/H91 -> 0.11295001 | I92: =I90/I91 -> 0.11117596
B94: Revenue | C94: =C91 -> 19240.13 | D94: =D91 -> 20211.25 | E94: =E91 -> 21712.79 | F94: =F91 -> 29101.28 | G94: =G91 -> 34488.59 | H94: =H91 -> 35494.73 | I94: =I91 -> 33905.62
B95: Average Total Asset | C95: =C85 -> 15006.16 | D95: =D85 -> 16193.405 | E95: =E85 -> 18246.655 | F95: =F85 -> 21656.885 | G95: =G85 -> 24368.88 | H95: =H85 -> 27840.05 | I95: =I85 -> 30128.01
B96: Asset Turnover Ratio (B) | C96: =C94/C95 -> 1.2821488 | D96: =D94/D95 -> 1.2481161 | E96: =E94/E95 -> 1.18996 | F96: =F94/F95 -> 1.3437426 | G96: =G94/G95 -> 1.4152719 | H96: =H94/H95 -> 1.2749521 | I96: =I94/I95 -> 1.1253853
B98: Return on Asset (A*B) | C98: =C96*C92 -> 0.16798368 | D98: =D96*D92 -> 0.17892716 | E98: =E96*E92 -> 0.16770197 | F98: =F96*F92 -> 0.25113815 | G98: =G96*G92 -> 0.17987409 | H98: =H96*H92 -> 0.14400585 | I98: =I96*I92 -> 0.1251158

Sheet Altman Z Score
B3: ='Dupont Analysis'!B3 -> ASIAN PAINTS LTD
B4: =CONCATENATE(" ","(",VLOOKUP(B3,'[2]List of Stocks'!A2:C5442,3,1)," | ","BSE Code: ",VLOOKUP(B3,'[2]List of Stocks'!A2:B5442,2,1),")") -> (ASIANPAINT | BSE Code: 500820)
B5: ='Dupont Analysis'!B5 -> INR 2519
B6: 52 Week (High - INR 3394.90 & Low - 2124.75)
B8: Altman's Z Score Analysis
B10: Financial Summary
B40: Working Capital / Total Assets
C41: ='Dupont Analysis'!C61 -> 43555 | D41: ='Dupont Analysis'!D61 -> 43921 | E41: ='Dupont Analysis'!E61 -> 44286 | F41: ='Dupont Analysis'!F61 -> 44651 | G41: ='Dupont Analysis'!G61 -> 45016 | H41: ='Dupont Analysis'!H61 -> 45382 | I41: ='Dupont Analysis'!I61 -> 45747
B42: Working Capital | C42: ='Data Sheet'!E65-'Data Sheet'!E60 -> 1515.34 | D42: ='Data Sheet'!F65-'Data Sheet'!F60 -> 2817.26 | E42: ='Data Sheet'!G65-'Data Sheet'!G60 -> 3121.11 | F42: ='Data Sheet'!H65-'Data Sheet'!H60 -> 6205.42 | G42: ='Data Sheet'!I65-'Data Sheet'!I60 -> 6873.09 | H42: ='Data Sheet'!J65-'Data Sheet'!J60 -> 6769.77 | I42: ='Data Sheet'!K65-'Data Sheet'!K60 -> 6490.76
B43: Total Assets | C43: ='Data Sheet'!E61 -> 16248.84 | D43: ='Data Sheet'!F61 -> 16137.97 | E43: ='Data Sheet'!G61 -> 20355.34 | F43: ='Data Sheet'!H61 -> 22958.43 | G43: ='Data Sheet'!I61 -> 25779.33 | H43: ='Data Sheet'!J61 -> 29900.77 | I43: ='Data Sheet'!K61 -> 30355.25
B44: Working Capital / Total Assets (A) | C44: =C42/C43 -> 0.09325835 | D44: =D42/D43 -> 0.17457338 | E44: =E42/E43 -> 0.15333126 | F44: =F42/F43 -> 0.27028939 | G44: =G42/G43 -> 0.26661244 | H44: =H42/H43 -> 0.22640788 | I44: =I42/I43 -> 0.2138266
B46: Retained Earnings / Total Assets
C47: =C41 -> 43555 | D47: =D41 -> 43921 | E47: =E41 -> 44286 | F47: =F41 -> 44651 | G47: =G41 -> 45016 | H47: =H41 -> 45382 | I47: =I41 -> 45747
B48: Retained Earnings | C48: =HistoricalFS!F36*HistoricalFS!F38*HistoricalFS!F44 -> 1513.63 | D48: =HistoricalFS!G36*HistoricalFS!G38*HistoricalFS!G44 -> 1746.4 | E48: =HistoricalFS!H36*HistoricalFS!H38*HistoricalFS!H44 -> 1347.83 | F48: =HistoricalFS!I36*HistoricalFS!I38*HistoricalFS!I44 -> 3602 | G48: =HistoricalFS!J36*HistoricalFS!J38*HistoricalFS!J44 -> 1922.98 | H48: =HistoricalFS!K36*HistoricalFS!K38*HistoricalFS!K44 -> 814.99 | I48: =HistoricalFS!L36*HistoricalFS!L38*HistoricalFS!L44 -> 1390.67
B49: Total Assets | C49: =C$43 -> 16248.84 | D49: =D$43 -> 16137.97 | E49: =E$43 -> 20355.34 | F49: =F$43 -> 22958.43 | G49: =G$43 -> 25779.33 | H49: =H$43 -> 29900.77 | I49: =I$43 -> 30355.25
B50: Retained Earnings / Total Assets (B) | C50: =C48/C49 -> 0.093153111 | D50: =D48/D49 -> 0.10821683 | E50: =E48/E49 -> 0.066215057 | F50: =F48/F49 -> 0.15689226 | G50: =G48/G49 -> 0.07459387 | H50: =H48/H49 -> 0.027256489 | I50: =I48/I49 -> 0.045813162
B52: EBIT / Total Assets
C53: =C41 -> 43555 | D53: =D41 -> 43921 | E53: =E41 -> 44286 | F53: =F41 -> 44651 | G53: =G41 -> 45016 | H53: =H41 -> 45382 | I53: =I41 -> 45747
B54: EBIT | C54: =HistoricalFS!F18-HistoricalFS!F24 -> 3729.32 | D54: =HistoricalFS!G18-HistoricalFS!G24 -> 3854.62 | E54: =HistoricalFS!H18-HistoricalFS!H24 -> 4249.23 | F54: =HistoricalFS!I18-HistoricalFS!I24 -> 6637.19 | G54: =HistoricalFS!J18-HistoricalFS!J24 -> 6021.28 | H54: =HistoricalFS!K18-HistoricalFS!K24 -> 6004.38 | I54: =HistoricalFS!L18-HistoricalFS!L24 -> 5389.87
B55: Total Assets | C55: =C$43 -> 16248.84 | D55: =D$43 -> 16137.97 | E55: =E$43 -> 20355.34 | F55: =F$43 -> 22958.43 | G55: =G$43 -> 25779.33 | H55: =H$43 -> 29900.77 | I55: =I$43 -> 30355.25
B56: EBIT/Total Assets (C) | C56: =C54/C55 -> 0.229513 | D56: =D54/D55 -> 0.23885408 | E56: =E54/E55 -> 0.20875259 | F56: =F54/F55 -> 0.28909599 | G56: =G54/G55 -> 0.23357007 | H56: =H54/H55 -> 0.20081021 | I56: =I54/I55 -> 0.17755973
B58: Market Cap / Long term Liabilities
C59: =C41 -> 43555 | D59: =D41 -> 43921 | E59: =E41 -> 44286 | F59: =F41 -> 44651 | G59: =G41 -> 45016 | H59: =H41 -> 45382 | I59: =I41 -> 45747
B60: Market Cap | C60: =('Data Sheet'!E90*'Data Sheet'!E70)/10000000 -> 143179.45 | D60: =('Data Sheet'!F90*'Data Sheet'!F70)/10000000 -> 159850.31 | E60: =('Data Sheet'!G90*'Data Sheet'!G70)/10000000 -> 243386.85 | F60: =('Data Sheet'!H90*'Data Sheet'!H70)/10000000 -> 295428.12 | G60: =('Data Sheet'!I90*'Data Sheet'!I70)/10000000 -> 264896.86 | H60: =('Data Sheet'!J90*'Data Sheet'!J70)/10000000 -> 273059.63 | I60: =('Data Sheet'!K90*'Data Sheet'!K70)/10000000 -> 241621.92
B61: Long term Liabilities | C61: ='Data Sheet'!E59 -> 1319.6 | D61: ='Data Sheet'!F59 -> 1118.5 | E61: ='Data Sheet'!G59 -> 1093.12 | F61: ='Data Sheet'!H59 -> 1586.88 | G61: ='Data Sheet'!I59 -> 1932.62 | H61: ='Data Sheet'!J59 -> 2474.38 | I61: ='Data Sheet'!K59 -> 2290.29
B62: Market Cap / Long term Liabilities (D) | C62: =C60/C61 -> 108.50216 | D62: =D60/D61 -> 142.9149 | E62: =E60/E61 -> 222.65337 | F62: =F60/F61 -> 186.16916 | G62: =G60/G61 -> 137.06619 | H62: =H60/H61 -> 110.35477 | I62: =I60/I61 -> 105.4984
B64: Sales / Total Assets
C65: =C41 -> 43555 | D65: =D41 -> 43921 | E65: =E41 -> 44286 | F65: =F41 -> 44651 | G65: =G41 -> 45016 | H65: =H41 -> 45382 | I65: =I41 -> 45747
B66: Total Sales | C66: =HistoricalFS!F6 -> 19240.13 | D66: =HistoricalFS!G6 -> 20211.25 | E66: =HistoricalFS!H6 -> 21712.79 | F66: =HistoricalFS!I6 -> 29101.28 | G66: =HistoricalFS!J6 -> 34488.59 | H66: =HistoricalFS!K6 -> 35494.73 | I66: =HistoricalFS!L6 -> 33905.62
B67: Total Assets | C67: =C55 -> 16248.84 | D67: =D55 -> 16137.97 | E67: =E55 -> 20355.34 | F67: =F55 -> 22958.43 | G67: =G55 -> 25779.33 | H67: =H55 -> 29900.77 | I67: =I55 -> 30355.25
B68: Return on Asset (E) | C68: =C66/C67 -> 1.1840925 | D68: =D66/D67 -> 1.2524035 | E68: =E66/E67 -> 1.0666877 | F68: =F66/F67 -> 1.267564 | G68: =G66/G67 -> 1.3378389 | H68: =H66/H67 -> 1.1870841 | I68: =I66/I67 -> 1.1169607
B70: Altman's Z Score
C71: =C41 -> 43555 | D71: =D41 -> 43921 | E71: =E41 -> 44286 | F71: =F41 -> 44651 | G71: =G41 -> 45016 | H71: =H41 -> 45382 | I71: =I41 -> 45747
B72: Final Score | C72: =(C44*1.2)+(C50*1.4)+(C56*3.3)+(C62*0.6)*(C68*1) -> 78.085677 | D72: =(D44*1.2)+(D50*1.4)+(D56*3.3)+(D62*0.6)*(D68*1) -> 108.54148 | E72: =(E44*1.2)+(E50*1.4)+(E56*3.3)+(E62*0.6)*(E68*1) -> 143.46654 | F72: =(F44*1.2)+(F50*1.4)+(F56*3.3)+(F62*0.6)*(F68*1) -> 143.08681 | G72: =(G44*1.2)+(G50*1.4)+(G56*3.3)+(G62*0.6)*(G68*1) -> 111.21863 | H72: =(H44*1.2)+(H50*1.4)+(H56*3.3)+(H62*0.6)*(H68*1) -> 79.57276 | I72: =(I44*1.2)+(I50*1.4)+(I56*3.3)+(I62*0.6)*(I68*1) -> 71.609213
B73: Financial Stability | C73: =IF(C72<1.81," Distressed",IF(C72>3,"Strong","Grey Zone")) -> Strong | D73: =IF(D72<1.81," Distressed",IF(D72>3,"Strong","Grey Zone")) -> Strong | E73: =IF(E72<1.81," Distressed",IF(E72>3,"Strong","Grey Zone")) -> Strong | F73: =IF(F72<1.81," Distressed",IF(F72>3,"Strong","Grey Zone")) -> Strong | G73: =IF(G72<1.81," Distressed",IF(G72>3,"Strong","Grey Zone")) -> Strong | H73: =IF(H72<1.81," Distressed",IF(H72>3,"Strong","Grey Zone")) -> Strong | I73: =IF(I72<1.81," Distressed",IF(I72>3,"Strong","Grey Zone")) -> Strong

Sheet VAR>

Sheet Historical Approach
B3: Value at Risk - Asian Paints Ltd. (Historical)
B5: Date | C5: Adj. Close | D5: Returns | E5: Sorted Returns | G5: Calculation of Value at Risk - Asian Paints Ltd.
B7: 43910 | C7: 1745.85 | D7: =(C7-C8)/C8 -> -0.3705473 | E7: 0.089114161 | G7: Mean | K7: =AVERAGE(E7:E2648) -> 0.00057895214
B8: 44330 | C8: 2773.6 | D8: =(C8-C9)/C9 -> 0.53725925 | E8: 0.085090568 | G8: Std. Deviation | K8: =_xlfn.STDEV.S(E7:E2648) -> 0.015516149
B9: 43731 | C9: 1804.25 | D9: =(C9-C10)/C10 -> 0.07887105 | E9: 0.07887105 | G9: Min | K9: =MIN(E7:E2648) -> -0.14153564
B10: 43728 | C10: 1672.35 | D10: =(C10-C11)/C11 -> 0.029740464 | E10: 0.075915978 | G10: Max | K10: =MAX(E7:E2648) -> 0.089114161
B11: 43928 | C11: 1624.05 | D11: =(C11-C12)/C12 -> -0.13031488 | E11: 0.067540919 | G11: CMP | K11: 2519
B12: 43864 | C12: 1867.4 | D12: =(C12-C13)/C13 -> 0.44804591 | E12: 0.063197449
B13: 43231 | C13: 1289.6 | D13: =(C13-C14)/C14 -> 0.14432761 | E13: 0.061661316 | G13: Percentile | H13: Confidence | I13: VAR% | J13: Stock Price | K13: VAR (INR)
B14: 42579 | C14: 1126.95 | D14: =(C14-C15)/C15 -> 0.37516779 | E14: 0.061358071 | G14: 0.05 | H14: =100%-G14 -> 0.95 | I14: =_xlfn.PERCENTILE.INC($E$7:$E$2648,G14) -> -0.022777133 | J14: =$K$11*(1-I14) -> 2576.3756 | K14: =$K$11-J14 -> -57.375597
B15: 42012 | C15: 819.5 | D15: =(C15-C16)/C16 -> -0.74059889 | E15: 0.061116147 | G15: 0.01 | H15: =100%-G15 -> 0.99 | I15: =_xlfn.PERCENTILE.INC($E$7:$E$2648,G15) -> -0.039418631 | J15: =$K$11*(1-I15) -> 2618.2955 | K15: =$K$11-J15 -> -99.295532
B16: 44397 | C16: 3159.2 | D16: =(C16-C17)/C17 -> 0.43720856 | E16: 0.060365516 | G16: 0.005 | H16: =100%-G16 -> 0.995 | I16: =_xlfn.PERCENTILE.INC($E$7:$E$2648,G16) -> -0.051234076 | J16: =$K$11*(1-I16) -> 2648.0586 | K16: =$K$11-J16 -> -129.05864
B17: 44131 | C17: 2198.15 | D17: =(C17-C18)/C18 -> -0.23545268 | E17: 0.056447349 | G17: 0.1 | H17: =100%-G17 -> 0.9 | I17: =_xlfn.PERCENTILE.INC($E$7:$E$2648,G17) -> -0.016193275 | J17: =$K$11*(1-I17) -> 2559.7909 | K17: =$K$11-J17 -> -40.790859
B18: 44629 | C18: 2875.1 | D18: =(C18-C19)/C19 -> 2.4860261 | E18: 0.055605529
B19: 42192 | C19: 824.75 | D19: =(C19-C20)/C20 -> -0.54500317 | E19: 0.052782742
B20: 43943 | C20: 1812.65 | D20: =(C20-C21)/C21 -> 0.15088889 | E20: 0.050446222
B21: 43972 | C21: 1575 | D21: =(C21-C22)/C22 -> -0.36255464 | E21: 0.049685094
B22: 44271 | C22: 2470.8 | D22: =(C22-C23)/C23 -> 1.6444052 | E22: 0.048748912
B23: 42690 | C23: 934.35 | D23: =(C23-C24)/C24 -> -0.58786556 | E23: 0.047242771
B24: 45722 | C24: 2267.1 | D24: =(C24-C25)/C25 -> 0.4222264 | E24: 0.047038448
B25: 43915 | C25: 1594.05 | D25: =(C25-C26)/C26 -> 0.3395941 | E25: 0.045107359
B26: 43397 | C26: 1189.95 | D26: =(C26-C27)/C27 -> 0.41475449 | E26: 0.044915701
B27: 42277 | C27: 841.1 | D27: =(C27-C28)/C28 -> -0.53402953 | E27: 0.044520335
B28: 44050 | C28: 1805.05 | D28: =(C28-C29)/C29 -> -0.078280185 | E28: 0.044438015
B29: 44064 | C29: 1958.35 | D29: =(C29-C30)/C30 -> -0.36709004 | E29: 0.044314091
... B39: 44292 | C39: 2612.65 | D39: =(C39-C40)/C40 -> 0.97337513 | E39: 0.040689106
B40: 43445 | C40: 1323.95 | D40: =(C40-C42)/C42 -> 0.090074513 | E40: 0.04026872
B42: 42979 | C42: 1214.55 | D42: =(C42-C43)/C43 -> -0.38603276 | E42: 0.039720926
B43: 44075 | C43: 1978.2 | D43: =(C43-C44)/C44 -> 0.11275489 | E43: 0.039298098
B44: 44039 | C44: 1777.75 | D44: =(C44-C45)/C45 -> -0.23250443 | E44: 0.039042637
B45: 44167 | C45: 2316.3 | D45: =(C45-C46)/C46 -> 1.4576127 | E45: 0.038839306
B46: 42697 | C46: 942.5 | D46: =(C46-C47)/C47 -> -0.36472095 | E46: 0.038739186
B47: 43670 | C47: 1483.6 | D47: =(C47-C48)/C48 -> -0.48466428 | E47: 0.038680996
B48: 45425 | C48: 2878.9 | D48: =(C48-C49)/C49 -> 1.6928257 | E48: 0.03826457
B49: 42808 | C49: 1069.1 | D49: =(C49-C50)/C50 -> -0.17647512 | E49: 0.038061948
B50: 43413 | C50: 1298.2 | D50: =(C50-C51)/C51 -> -0.60229153 | E50: 0.037854259
B51: 44607 | C51: 3264.2 | D51: =(C51-C52)/C52 -> 0.38135037 | E51: 0.037604501
B52: 44256 | C52: 2363.05 | D52: =(C52-C53)/C53 -> 0.8732065 | E52: 0.037585897
B53: 43385 | C53: 1261.5 | D53: =(C53-C54)/C54 -> -0.27765689 | E53: 0.037375108
... B2648: 43913 | C2648: 1498.75 | D2648: =(C2648-C2649)/C2649 -> #DIV/0! | E2648: -0.14153564

Sheet Monte Carlo
B3: Value at Risk - Asian Paints Ltd. (Monte Carlo)
B5: Date | C5: Adj. Close | D5: Returns | E5: Sorted Returns | G5: Replication | H5: Simulation Returns | J5: Calculation of Value at Risk - Asian Paints Ltd.
B7: 43910 | C7: 1745.85 | D7: =(C7-C8)/C8 -> -0.3705473 | E7: 0.089114161 | G7: 1 | H7: =_xlfn.NORM.INV(RAND(),N$9,N$10) -> 0.0070364041
B8: 44330 | C8: 2773.6 | D8: =(C8-C9)/C9 -> 0.53725925 | E8: 0.085090568 | G8: 2 | H8: =_xlfn.NORM.INV(RAND(),N$9,N$10) -> -0.0069259517 | J8: Historical Approach
B9: 43731 | C9: 1804.25 | D9: =(C9-C10)/C10 -> 0.07887105 | E9: 0.07887105 | G9: 3 | H9: =_xlfn.NORM.INV(RAND(),N$9,N$10) -> 0.018246025 | J9: Mean | N9: =AVERAGE(E7:E2647) -> 0.00057895214
B10: 43728 | C10: 1672.35 | D10: =(C10-C11)/C11 -> 0.029740464 | E10: 0.075915978 | G10: 4 | H10: =_xlfn.NORM.INV(RAND(),N$9,N$10) -> -0.020941179 | J10: Std. Deviation | N10: =_xlfn.STDEV.S(E7:E2647) -> 0.015516149
B11: 43928 | C11: 1624.05 | D11: =(C11-C12)/C12 -> -0.13031488 | E11: 0.067540919 | G11: 5 | H11: =_xlfn.NORM.INV(RAND(),N$9,N$10) -> -0.009682489 | J11: Min | N11: =MIN(E7:E2647) -> -0.14153564
B12: 43864 | C12: 1867.4 | D12: =(C12-C13)/C13 -> 0.44804591 | E12: 0.063197449 | G12: 6 | H12: =_xlfn.NORM.INV(RAND(),N$9,N$10) -> -0.012052257 | J12: Max | N12: =MAX(E7:E2647) -> 0.089114161
B13: 43231 | C13: 1289.6 | D13: =(C13-C14)/C14 -> 0.14432761 | E13: 0.061661316 | G13: 7 | H13: =_xlfn.NORM.INV(RAND(),N$9,N$10) -> 0.013586859 | J13: CMP | N13: 2519
B14: 42579 | C14: 1126.95 | D14: =(C14-C15)/C15 -> 0.37516779 | E14: 0.061358071 | G14: 8 | H14: =_xlfn.NORM.INV(RAND(),N$9,N$10) -> -0.020294313
B15: 42012 | C15: 819.5 | D15: =(C15-C16)/C16 -> -0.74059889 | E15: 0.061116147 | G15: 9 | H15: =_xlfn.NORM.INV(RAND(),N$9,N$10) -> -0.0166487 | J15: Monte Carlo Simulation
B16: 44397 | C16: 3159.2 | D16: =(C16-C17)/C17 -> 0.43720856 | E16: 0.060365516 | G16: 10 | H16: =_xlfn.NORM.INV(RAND(),N$9,N$10) -> 0.0060725629 | J16: Mean | N16: =AVERAGE(H7:H10006) -> 0.00046064922
B17: 44131 | C17: 2198.15 | D17: =(C17-C18)/C18 -> -0.23545268 | E17: 0.056447349 | G17: 11 | H17: =_xlfn.NORM.INV(RAND(),N$9,N$10) -> 0.041200783 | J17: Std. Deviation | N17: =_xlfn.STDEV.S(H7:H10006) -> 0.01537875
B18: 44629 | C18: 2875.1 | D18: =(C18-C19)/C19 -> 2.4860261 | E18: 0.055605529 | G18: 12 | H18: =_xlfn.NORM.INV(RAND(),N$9,N$10) -> 0.026310555 | J18: Min | N18: =MIN(H7:H10006) -> -0.05707688
B19: 42192 | C19: 824.75 | D19: =(C19-C20)/C20 -> -0.54500317 | E19: 0.052782742 | G19: 13 | H19: =_xlfn.NORM.INV(RAND(),N$9,N$10) -> -0.0082735113 | J19: Max | N19: =MAX(H7:H10006) -> 0.060625364
B20: 43943 | C20: 1812.65 | D20: =(C20-C21)/C21 -> 0.15088889 | E20: 0.050446222 | G20: 14 | H20: =_xlfn.NORM.INV(RAND(),N$9,N$10) -> -0.015613953 | J20: CMP | N20: 2519
B21: 43972 | C21: 1575 | D21: =(C21-C22)/C22 -> -0.36255464 | E21: 0.049685094 | G21: 15 | H21: =_xlfn.NORM.INV(RAND(),N$9,N$10) -> -0.018863177
B22: 44271 | C22: 2470.8 | D22: =(C22-C23)/C23 -> 1.6444052 | E22: 0.048748912 | G22: 16 | H22: =_xlfn.NORM.INV(RAND(),N$9,N$10) -> 0.011156055 | J22: Percentile | K22: Confidence | L22: VAR% | M22: Stock Price | N22: VAR (INR)
B23: 42690 | C23: 934.35 | D23: =(C23-C24)/C24 -> -0.58786556 | E23: 0.047242771 | G23: 17 | H23: =_xlfn.NORM.INV(RAND(),N$9,N$10) -> -0.027792355 | J23: 0.05 | K23: =100%-J23 -> 0.95 | L23: =_xlfn.PERCENTILE.INC($H$7:$H$10006,J23) -> -0.024675891 | M23: =$N$13*(1-L23) -> 2581.1586 | N23: =$N$13-M23 -> -62.158569
B24: 45722 | C24: 2267.1 | D24: =(C24-C25)/C25 -> 0.4222264 | E24: 0.047038448 | G24: 18 | H24: =_xlfn.NORM.INV(RAND(),N$9,N$10) -> 0.0057045031 | J24: 0.01 | K24: =100%-J24 -> 0.99 | L24: =_xlfn.PERCENTILE.INC($H$7:$H$10006,J24) -> -0.033929517 | M24: =$N$13*(1-L24) -> 2604.4685 | N24: =$N$13-M24 -> -85.468452
B25: 43915 | C25: 1594.05 | D25: =(C25-C26)/C26 -> 0.3395941 | E25: 0.045107359 | G25: 19 | H25: =_xlfn.NORM.INV(RAND(),N$9,N$10) -> 0.0203278 | J25: 0.005 | K25: =100%-J25 -> 0.995 | L25: =_xlfn.PERCENTILE.INC($H$7:$H$10006,J25) -> -0.037780465 | M25: =$N$13*(1-L25) -> 2614.169 | N25: =$N$13-M25 -> -95.168992
B26: 43397 | C26: 1189.95 | D26: =(C26-C27)/C27 -> 0.41475449 | E26: 0.044915701 | G26: 20 | H26: =_xlfn.NORM.INV(RAND(),N$9,N$10) -> -0.015865195 | J26: 0.1 | K26: =100%-J26 -> 0.9 | L26: =_xlfn.PERCENTILE.INC($H$7:$H$10006,J26) -> -0.019151081 | M26: =$N$13*(1-L26) -> 2567.2416 | N26: =$N$13-M26 -> -48.241572
B27: 42277 | C27: 841.1 | D27: =(C27-C28)/C28 -> -0.53402953 | E27: 0.044520335 | G27: 21 | H27: =_xlfn.NORM.INV(RAND(),N$9,N$10) -> -0.0033514734
B28: 44050 | C28: 1805.05 | D28: =(C28-C29)/C29 -> -0.078280185 | E28: 0.044438015 | G28: 22 | H28: =_xlfn.NORM.INV(RAND(),N$9,N$10) -> -0.018364327
B29: 44064 | C29: 1958.35 | D29: =(C29-C30)/C30 -> -0.36709004 | E29: 0.044314091 | G29: 23 | H29: =_xlfn.NORM.INV(RAND(),N$9,N$10) -> -0.011254337
B30: 44496 | C30: 3094.2 | D30: =(C30-C31)/C31 -> 0.85648287 | E30: 0.044226583 | G30: 24 | H30: =_xlfn.NORM.INV(RAND(),N$9,N$10) -> 0.023081111
B31: 43921 | C31: 1666.7 | D31: =(C31-C32)/C32 -> -0.33453115 | E31: 0.043546317 | G31: 25 | H31: =_xlfn.NORM.INV(RAND(),N$9,N$10) -> 0.0099956519
B32: 44281 | C32: 2504.55 | D32: =(C32-C33)/C33 -> 0.21409181 | E32: 0.042758707 | G32: 26 | H32: =_xlfn.NORM.INV(RAND(),N$9,N$10) -> 0.013949466
B33: 44084 | C33: 2062.9 | D33: =(C33-C34)/C34 -> 1.368699 | E33: 0.042500505 | G33: 27 | H33: =_xlfn.NORM.INV(RAND(),N$9,N$10) -> -0.034644527
B34: 42345 | C34: 870.9 | D34: =(C34-C35)/C35 -> -0.36558004 | E34: 0.041621816 | G34: 28 | H34: =_xlfn.NORM.INV(RAND(),N$9,N$10) -> -0.011693497
B35: 43605 | C35: 1372.75 | D35: =(C35-C36)/C36 -> 0.72792498 | E35: 0.041421689 | G35: 29 | H35: =_xlfn.NORM.INV(RAND(),N$9,N$10) -> 0.0066497025
B36: 42138 | C36: 794.45 | D36: =(C36-C37)/C37 -> -0.34907825 | E36: 0.041218873 | G36: 30 | H36: =_xlfn.NORM.INV(RAND(),N$9,N$10) -> 0.019048309
B37: 43032 | C37: 1220.5 | D37: =(C37-C38)/C38 -> -0.49374702 | E37: 0.041026953 | G37: 31 | H37: =_xlfn.NORM.INV(RAND(),N$9,N$10) -> 0.0091883428
B38: 44168 | C38: 2410.85 | D38: =(C38-C39)/C39 -> -0.077239584 | E38: 0.04081941 | G38: 32 | H38: =_xlfn.NORM.INV(RAND(),N$9,N$10) -> -0.011257909
... B2647: 43913 | C2647: 1498.75 | D2647: =(C2647-C2648)/C2648 -> #DIV/0! | E2647: -0.14153564 | G2647: 2641 | H2647: =_xlfn.NORM.INV(RAND(),N$9,N$10) -> 0.0071825011
G2648: 2642 | H2648: =_xlfn.NORM.INV(RAND(),N$9,N$10) -> 0.015382464
G2649: 2643 | H2649: =_xlfn.NORM.INV(RAND(),N$9,N$10) -> 0.00076792231
G2650: 2644 | H2650: =_xlfn.NORM.INV(RAND(),N$9,N$10) -> -0.017972665
G2651: 2645 | H2651: =_xlfn.NORM.INV(RAND(),N$9,N$10) -> -0.0092114577
G2652: 2646 | H2652: =_xlfn.NORM.INV(RAND(),N$9,N$10) -> -0.033672363
...

Sheet Stk Data
A2: Date | B2: Adj. Close | M2: Date | N2: Total Turnover (Rs.)
A3: 44197 | B3: 2775 | M3: 44197 | N3: 144.66687 | O3: 1000000
A4: 44200 | B4: 2754.8 | M4: 44200 | N4: 126.01642
A5: 44201 | B5: 2793.25 | M5: 44201 | N5: 206.81007
A6: 44202 | B6: 2803.15 | M6: 44202 | N6: 121.21768
A7: 44203 | B7: 2791.35 | M7: 44203 | N7: 2360.0694
A8: 44204 | B8: 2844 | M8: 44204 | N8: 94.850617
A9: 44207 | B9: 2849.2 | M9: 44207 | N9: 138.57914
A10: 44208 | B10: 2737.3 | M10: 44208 | N10: 498.14647
A11: 44209 | B11: 2704.5 | M11: 44209 | N11: 317.39955
A12: 44210 | B12: 2663.5 | M12: 44210 | N12: 529.5037
A13: 44211 | B13: 2590 | M13: 44211 | N13: 158.76397
A14: 44214 | B14: 2589.05 | M14: 44214 | N14: 178.14425
A15: 44215 | B15: 2645.6 | M15: 44215 | N15: 327.6484
... A1158: 45898 | B1158: 2517.4 | M1158: 45898 | N1158: 137.32995

Sheet DCF>

Sheet WACC
B3: Weighted Average Cost of Capital
B5: All figures are in INR unless stated otherwise.
B6: Amount in crores
B7: Peer Comps
G8: Debt/ | H8: Debt/ | I8: Levered | J8: Unlevered
B9: Name | C9: Country | D9: Total Debt | E9: Total Equity | F9: Tax Rate 1 | G9: Equity | H9: Capital | I9: Beta 2 | J9: Beta 3
B11: ='Beta Comps'!D4 -> Asian Paints | C11: India | D11: ='Beta Comps'!G4 -> 2290.29 | E11: ='Beta Comps'!F4 -> 238614.8 | F11: 0.3 | G11: =D11/E11 -> 0.009598273 | H11: =D11/(D11+E11) -> 0.009507022 | I11: ='Beta - Regression'!M7 -> 0.16859133 | J11: =I11/(1+(1-F11)*G11) -> 0.16746616
B12: ='Beta Comps'!D5 -> Berger Paints | C12: India | D12: ='Beta Comps'!G5 -> 670.27 | E12: ='Beta Comps'!F5 -> 61280.41 | F12: 0.3 | G12: =D12/E12 -> 0.010937753 | H12: =D12/(D12+E12) -> 0.010819413 | I12: 0.752 | J12: =I12/(1+(1-F12)*G12) -> 0.74628611
B13: ='Beta Comps'!D6 -> Kansai Nerolac | C13: India | D13: ='Beta Comps'!G6 -> 296.39 | E13: ='Beta Comps'!F6 -> 18926.24 | F13: 0.3 | G13: =D13/E13 -> 0.015660268 | H13: =D13/(D13+E13) -> 0.015418806 | I13: 0.88 | J13: =I13/(1+(1-F13)*G13) -> 0.87045788
B14: ='Beta Comps'!D7 -> Akzo Nobel | C14: India | D14: ='Beta Comps'!G7 -> 62.1 | E14: ='Beta Comps'!F7 -> 15646.37 | F14: 0.3 | G14: =D14/E14 -> 0.0039689717 | H14: =D14/(D14+E14) -> 0.0039532813 | I14: 0.04 | J14: =I14/(1+(1-F14)*G14) -> 0.039889177
B15: ='Beta Comps'!D8 -> Indigo Paints | C15: India | D15: ='Beta Comps'!G8 -> 19.7 | E15: ='Beta Comps'!F8 -> 5271.68 | F15: 0.3 | G15: =D15/E15 -> 0.0037369491 | H15: =D15/(D15+E15) -> 0.0037230363 | I15: 0.97 | J15: =I15/(1+(1-F15)*G15) -> 0.96746923
E17: Average | F17: =AVERAGE(F11:F15) -> 0.3 | G17: =AVERAGE(G11:G15) -> 0.0087804431 | H17: =AVERAGE(H11:H15) -> 0.0086843117 | I17: =AVERAGE(I11:I15) -> 0.56211827 | J17: =AVERAGE(J11:J15) -> 0.55831371
E18: Median | F18: =MEDIAN(F11:F15) -> 0.3 | G18: =MEDIAN(G11:G15) -> 0.009598273 | H18: =MEDIAN(H11:H15) -> 0.009507022 | I18: =MEDIAN(I11:I15) -> 0.752 | J18: =MEDIAN(J11:J15) -> 0.74628611
B21: Cost of Debt | G21: Cost of Equity
B23: Pre-tax Cost of Debt | E23: =227/2290.29 -> 0.099114086 | G23: Risk Free Rate | J23: 0.0662
B24: Tax Rate | E24: =F18 -> 0.3 | G24: Equity Risk Premium | J24: =Rm!F8-J23 -> 0.087148
B25: After Tax Cost of Debt | E25: =E23*(1-E24) -> 0.06937986 | G25: Levered Beta 4 | J25: =J34 -> 0.96821062
G26: Cost of Equity | J26: =J23+(J24*J25) -> 0.15057762
B29: Capital Structure | G29: Levered Beta
D31: Current | E31: Target | G31: Comps Median Unlevered Beta | J31: =J18 -> 0.74628611
B32: Total Debt | C32: =D11 -> 2290.29 | D32: =C32/$C$34 -> 0.009507022 | E32: =H17 -> 0.0086843117 | G32: Target Debt/ Equity | J32: =E36 -> 0.0087603897
B33: Market Capitalization | C33: =E11 -> 238614.8 | D33: =C33/$C$34 -> 0.99049298 | E33: =E34-E32 -> 0.99131569 | G33: Tax Rate | J33: =E24 -> 0.3
B34: Total Capitalization | C34: =SUM(C32:C33) -> 240905.09 | D34: =C34/$C$34 -> 1 | E34: =D34 -> 1 | G34: Levered Beta | J34: =J31*(1+(1-J32)*J33) -> 0.96821062
B36: Debt / Equity | D36: =D32/D33 -> 0.009598273 | E36: =E32/E33 -> 0.0087603897 | G36: Weighted Average Cost of Capital
B38: 1. Tax Rate considered as Marginal Tax Rate for the country | G38: Cost of Equity | J38: =J26 -> 0.15057762
B39: 2. Levered Beta is based on 5 year monthly data | G39: Equity Weight | J39: =E33 -> 0.99131569
B40: 3. Unlevered Beta = Levered Beta/(1+(1-Tax Rate) x Debt/Equity)
B41: 3. Levered Beta = Unlevered Beta/(1+(1-Tax Rate) x Debt/Equity) | G41: Cost of Debt | J41: =E25 -> 0.06937986
G42: Debt Weight | J42: =E32 -> 0.0086843117
G44: WACC | J44: =(J38*J39)+(J41*J42) -> 0.14987247

Sheet Data>

Sheet Beta - Regression
B2: Regression Beta - 2 Years Weekly
B4: Asian Paints Ltd. Weekly Returns | F4: Nifty Returns | I4: Beta Drifting | L4: Beta 1 | M4: =SLOPE(D8:D111,G8:G111) -> 0.16859133
L5: Beta 2 | M5: =_xlfn.COVARIANCE.S(D8:D111,G8:G111)/_xlfn.VAR.S(G8:G111) -> 0.16859133
B6: Date | C6: Closing Price | D6: Returns | F6: Closing Price | G6: Returns | I6: Levered Beta | J6: =M7 -> 0.16859133
B7: 45165 | C7: 3259.55 | F7: 24695.9 | I7: Raw Beta Weight | J7: 0.75 | L7: Beta 3 | M7: =M27 -> 0.16859133
B8: 45172 | C8: 3238.05 | D8: =C8/C7-1 -> -0.0065960025 | F8: 24870.1 | G8: =F8/F7-1 -> 0.0070538025
B9: 45179 | C9: 3196.65 | D9: =C9/C8-1 -> -0.012785473 | F9: 24631.3 | G9: =F9/F8-1 -> -0.0096018914 | I9: Market Beta | J9: 1
B10: 45186 | C10: 3274.85 | D10: =C10/C9-1 -> 0.02446311 | F10: 24363.3 | G10: =F10/F9-1 -> -0.010880465 | I10: Market Beta Weight | J10: 0.25 | L10: SUMMARY OUTPUT
B11: 45193 | C11: 3161.05 | D11: =C11/C10-1 -> -0.034749683 | F11: 24565.35 | G11: =F11/F10-1 -> 0.0082932115
B12: 45200 | C12: 3195.75 | D12: =C12/C11-1 -> 0.010977365 | F12: 24837 | G12: =F12/F11-1 -> 0.011058259 | I12: Adjusted Beta | J12: =(J6*J7)+(J9*J10) -> 0.3764435 | L12: Regression Statistics
B13: 45207 | C13: 3148.8 | D13: =C13/C12-1 -> -0.014691387 | F13: 24968.4 | G13: =F13/F12-1 -> 0.005290494 | L13: Multiple R | M13: 0.10866336
B14: 45214 | C14: 3105.85 | D14: =C14/C13-1 -> -0.013640117 | F14: 25149.85 | G14: =F14/F13-1 -> 0.0072671857 | L14: R Square | M14: 0.011807726
B15: 45221 | C15: 2955.15 | D15: =C15/C14-1 -> -0.048521339 | F15: 25461 | G15: =F15/F14-1 -> 0.012371843 | L15: Adjusted R Square | M15: 0.0021195663
B16: 45228 | C16: 2977.85 | D16: =C16/C15-1 -> 0.0076815052 | F16: 25637.8 | G16: =F16/F15-1 -> 0.0069439535 | L16: Standard Error | M16: 0.02674078
B17: 45235 | C17: 3076.45 | D17: =C17/C16-1 -> 0.033111137 | F17: 25112.4 | G17: =F17/F16-1 -> -0.020493178 | L17: Observations | M17: 104
B18: 45242 | C18: 3168.9 | D18: =C18/C17-1 -> 0.03005087 | F18: 24718.6 | G18: =F18/F17-1 -> -0.015681496
B19: 45249 | C19: 3136.15 | D19: =C19/C18-1 -> -0.010334816 | F19: 25003.05 | G19: =F19/F18-1 -> 0.011507529 | L19: ANOVA
B20: 45256 | C20: 3173.4 | D20: =C20/C19-1 -> 0.011877621 | F20: 24750.7 | G20: =F20/F19-1 -> -0.010092769 | M20: df | N20: SS | O20: MS | P20: F | Q20: Significance F
B21: 45263 | C21: 3232 | D21: =C21/C20-1 -> 0.018465999 | F21: 24853.15 | G21: =F21/F20-1 -> 0.0041392769 | L21: Regression | M21: 1 | N21: 0.00087151152 | O21: 0.00087151152 | P21: 1.218779 | Q21: 0.27219801
B22: 45270 | C22: 3313.9 | D22: =C22/C21-1 -> 0.025340347 | F22: 25019.8 | G22: =F22/F21-1 -> 0.0067053874 | L22: Residual | M22: 102 | N22: 0.072937072 | O22: 0.00071506933
B23: 45277 | C23: 3341.3 | D23: =C23/C22-1 -> 0.0082682036 | F23: 24008 | G23: =F23/F22-1 -> -0.040439972 | L23: Total | M23: 103 | N23: 0.073808583
B24: 45284 | C24: 3402.4 | D24: =C24/C23-1 -> 0.018286296 | F24: 24346.7 | G24: =F24/F23-1 -> 0.014107797
B25: 45291 | C25: 3355.55 | D25: =C25/C24-1 -> -0.013769692 | F25: 24039.35 | G25: =F25/F24-1 -> -0.012623887 | M25: Coefficients | N25: Standard Error | O25: t Stat | P25: P-value | Q25: Lower 95% | R25: Upper 95% | S25: Lower 95.0% | T25: Upper 95.0%
B26: 45298 | C26: 3277.8 | D26: =C26/C25-1 -> -0.023170568 | F26: 23851.65 | G26: =F26/F25-1 -> -0.0078080314 | L26: Intercept | M26: -0.0019008789 | N26: 0.002642691 | O26: -0.7192967 | P26: 0.4736029 | Q26: -0.007142644 | R26: 0.0033408861 | S26: -0.007142644 | T26: 0.0033408861
B27: 45305 | C27: 3165.85 | D27: =C27/C26-1 -> -0.034154006 | F27: 22828.55 | G27: =F27/F26-1 -> -0.042894307 | L27: X Variable 1 | M27: 0.16859133 | N27: 0.15271186 | O27: 1.1039833 | P27: 0.27219801 | Q27: -0.13431191 | R27: 0.47149457 | S27: -0.13431191 | T27: 0.47149457
B28: 45312 | C28: 2949.2 | D28: =C28/C27-1 -> -0.068433438 | F28: 22904.45 | G28: =F28/F27-1 -> 0.0033247841
B29: 45319 | C29: 2936.3 | D29: =C29/C28-1 -> -0.0043740675 | F29: 23519.35 | G29: =F29/F28-1 -> 0.026846312
B30: 45326 | C30: 2951.65 | D30: =C30/C29-1 -> 0.0052276675 | F30: 23350.4 | G30: =F30/F29-1 -> -0.0071834468
B31: 45333 | C31: 3007.9 | D31: =C31/C30-1 -> 0.019057138 | F31: 22397.2 | G31: =F31/F30-1 -> -0.040821571
B32: 45340 | C32: 2985.95 | D32: =C32/C31-1 -> -0.00729745 | F32: 22552.5 | G32: =F32/F31-1 -> 0.0069339025
B33: 45347 | C33: 2831.75 | D33: =C33/C32-1 -> -0.051641856 | F33: 22124.7 | G33: =F33/F32-1 -> -0.018969072
B34: 45354 | C34: 2870.55 | D34: =C34/C33-1 -> 0.013701775 | F34: 22795.9 | G34: =F34/F33-1 -> 0.030337135
B35: 45361 | C35: 2867.55 | D35: =C35/C34-1 -> -0.0010450959 | F35: 22929.25 | G35: =F35/F34-1 -> 0.0058497361
B36: 45368 | C36: 2841.5 | D36: =C36/C35-1 -> -0.00908441 | F36: 23559.95 | G36: =F36/F35-1 -> 0.027506351
B37: 45375 | C37: 2846.75 | D37: =C37/C36-1 -> 0.0018476157 | F37: 23508.4 | G37: =F37/F36-1 -> -0.0021880352
B38: 45382 | C38: 2883.45 | D38: =C38/C37-1 -> 0.012891894 | F38: 23092.2 | G38: =F38/F37-1 -> -0.01770431
B39: 45389 | C39: 2854.5 | D39: =C39/C38-1 -> -0.010040056 | F39: 23203.2 | G39: =F39/F38-1 -> 0.0048068179
... B111: 45893 | C111: 2479.9 | D111: =C111/C110-1 -> -0.0098223198 | F111: 19435.3 | G111: =F111/F110-1 -> -0.019407213

Sheet Beta Comps
C3: S.No. | D3: Name | E3: CMP Rs. | F3: Mar Cap Rs.Cr. | G3: Debt Rs.Cr. | H3: Debt / Eq
C4: 1 | D4: Asian Paints | E4: 2487.45 | F4: 238614.8 | G4: 2290.29 | H4: 0.12
C5: 2 | D5: Berger Paints | E5: 526.1 | F5: 61280.41 | G5: 670.27 | H5: 0.11
C6: 3 | D6: Kansai Nerolac | E6: 234.1 | F6: 18926.24 | G6: 296.39 | H6: 0.05
C7: 4 | D7: Akzo Nobel | E7: 3430.9 | F7: 15646.37 | G7: 62.1 | H7: 0.05
C8: 5 | D8: Indigo Paints | E8: 1106 | F8: 5271.68 | G8: 19.7 | H8: 0.02

Sheet Rm
B4: Returns on Markets
B6: Year | C6: Annual | E6: Average Return | F6: =AVERAGE(C7:C31)/100 -> 0.153348
B7: 2000 | C7: -14.65 | E7: Dividend Yield | F7: 1.38% 1
B8: 2001 | C8: -16.18 | E8: Total Market Return | F8: =SUM(F6:F7) -> 0.153348
B9: 2002 | C9: 3.25
B10: 2003 | C10: 71.9
B11: 2004 | C11: 10.68
B12: 2005 | C12: 36.34
B13: 2006 | C13: 39.83
B14: 2007 | C14: 54.77
B15: 2008 | C15: -51.79
B16: 2009 | C16: 75.76
B17: 2010 | C17: 17.95
B18: 2011 | C18: -24.62
B19: 2012 | C19: 27.7
B20: 2013 | C20: 6.76
... B31: 2024 | C31: 8.75

Sheet Intrinsic Growth
B2: ="Instrinsic Growth"&" - "&'Data Sheet'!B1 -> Instrinsic Growth - ASIAN PAINTS LTD
B4: Calculation of ROIC | G4: ='Raw FS'!H2 -> 44256 | H4: ='Raw FS'!I2 -> 44621 | I4: ='Raw FS'!J2 -> 44986 | J4: ='Raw FS'!K2 -> 45352 | K4: ='Raw FS'!L2 -> 45717
B5: Amount in crores
B6: Current Assets
B7: ='Raw FS'!B35 -> Inventories | G7: ='Raw FS'!H35 -> 3799 | H7: ='Raw FS'!I35 -> 6153 | I7: ='Raw FS'!J35 -> 6211 | J7: ='Raw FS'!K35 -> 5923 | K7: ='Raw FS'!L35 -> 6719
B8: ='Raw FS'!B36 -> Trade receivables | G8: ='Raw FS'!H36 -> 2602 | H8: ='Raw FS'!I36 -> 3871 | I8: ='Raw FS'!J36 -> 4637 | J8: ='Raw FS'!K36 -> 4889 | K8: ='Raw FS'!L36 -> 4314
B9: ='Raw FS'!B38 -> Loans n Advances | G9: ='Raw FS'!H38 -> 11 | H9: ='Raw FS'!I38 -> 8 | I9: ='Raw FS'!J38 -> 12 | J9: ='Raw FS'!K38 -> 17 | K9: ='Raw FS'!L38 -> 22
B10: ='[3]Raw FS'!$B$39 -> Other asset items | G10: ='Raw FS'!H39 -> 2555 | H10: ='Raw FS'!I39 -> 2869 | I10: ='Raw FS'!J39 -> 3024 | J10: ='Raw FS'!K39 -> 3555 | K10: ='Raw FS'!L39 -> 3319
B11: Total Current Assets | G11: =SUM(G7:G10) -> 8967 | H11: =SUM(H7:H10) -> 12901 | I11: =SUM(I7:I10) -> 13884 | J11: =SUM(J7:J10) -> 14384 | K11: =SUM(K7:K10) -> 14374
B13: Current Liabilities
B14: ='Raw FS'!B13 -> Trade Payables | G14: ='Raw FS'!H13 -> 3379 | H14: ='Raw FS'!I13 -> 4164 | I14: ='Raw FS'!J13 -> 3635 | J14: ='Raw FS'!K13 -> 3831 | K14: ='Raw FS'!L13 -> 3848
B15: ='Raw FS'!B14 -> Advance from Customers | G15: ='Raw FS'!H14 -> 41 | H15: ='Raw FS'!I14 -> 76 | I15: ='Raw FS'!J14 -> 108 | J15: ='Raw FS'!K14 -> 154 | K15: ='Raw FS'!L14 -> 173
B16: ='Raw FS'!B15 -> Other liability items | G16: ='Raw FS'!H15 -> 2613 | H16: ='Raw FS'!I15 -> 2932 | I16: ='Raw FS'!J15 -> 3657 | J16: ='Raw FS'!K15 -> 4017 | K16: ='Raw FS'!L15 -> 3985
B17: Total Current Liabilities | G17: =SUM(G14:G16) -> 6033 | H17: =SUM(H14:H16) -> 7172 | I17: =SUM(I14:I16) -> 7400 | J17: =SUM(J14:J16) -> 8002 | K17: =SUM(K14:K16) -> 8006
B19: Net Working Capital | G19: =G11-G17 -> 2934 | H19: =H11-H17 -> 5729 | I19: =I11-I17 -> 6484 | J19: =J11-J17 -> 6382 | K19: =K11-K17 -> 6368
B21: Non Current Assets
B22: ='Raw FS'!B19 -> Land | G22: ='Raw FS'!H19 -> 644 | H22: ='Raw FS'!I19 -> 644 | I22: ='Raw FS'!J19 -> 804 | J22: ='Raw FS'!K19 -> 1126 | K22: ='Raw FS'!L19 -> 1050
B23: ='Raw FS'!B20 -> Building | G23: ='Raw FS'!H20 -> 2249 | H23: ='Raw FS'!I20 -> 2325 | I23: ='Raw FS'!J20 -> 2883 | J23: ='Raw FS'!K20 -> 3390 | K23: ='Raw FS'!L20 -> 4136
B24: ='Raw FS'!B21 -> Plant Machinery | G24: ='Raw FS'!H21 -> 4340 | H24: ='Raw FS'!I21 -> 4531 | I24: ='Raw FS'!J21 -> 4825 | J24: ='Raw FS'!K21 -> 5422 | K24: ='Raw FS'!L21 -> 7576
B25: ='Raw FS'!B22 -> Equipments | G25: ='Raw FS'!H22 -> 243 | H25: ='Raw FS'!I22 -> 253 | I25: ='Raw FS'!J22 -> 270 | J25: ='Raw FS'!K22 -> 298 | K25: ='Raw FS'!L22 -> 325
B26: ='Raw FS'!B23 -> Furniture n fittings | G26: ='Raw FS'!H23 -> 99 | H26: ='Raw FS'!I23 -> 113 | I26: ='Raw FS'!J23 -> 146 | J26: ='Raw FS'!K23 -> 175 | K26: ='Raw FS'!L23 -> 203
B27: ='Raw FS'!B24 -> Vehicles | G27: ='Raw FS'!H24 -> 38 | H27: ='Raw FS'!I24 -> 32 | I27: ='Raw FS'!J24 -> 36 | J27: ='Raw FS'!K24 -> 40 | K27: ='Raw FS'!L24 -> 39
B28: ='Raw FS'!B25 -> Intangible Assets | G28: ='Raw FS'!H25 -> 476 | H28: ='Raw FS'!I25 -> 345 | I28: ='Raw FS'!J25 -> 422 | J28: ='Raw FS'!K25 -> 850 | K28: ='Raw FS'!L25 -> 827
B29: ='Raw FS'!B26 -> Other fixed assets | G29: ='Raw FS'!H26 -> 302 | H29: ='Raw FS'!I26 -> 294 | I29: ='Raw FS'!J26 -> 289 | J29: ='Raw FS'!K26 -> 321 | K29: ='Raw FS'!L26 -> 328
B31: Gross Block | G31: =SUM(G22:G30) -> 8391 | H31: =SUM(H22:H30) -> 8537 | I31: =SUM(I22:I30) -> 9675 | J31: =SUM(J22:J30) -> 11622 | K31: =SUM(K22:K30) -> 14484
B32: Accumulated Depreciation | G32: ='Raw FS'!H28 -> 2533 | H32: ='Raw FS'!I28 -> 3019 | I32: ='Raw FS'!J28 -> 3905 | J32: ='Raw FS'!K28 -> 4475 | K32: ='Raw FS'!L28 -> 5264
B33: Net Non Current Assets | G33: =SUM(G31:G32) -> 10924 | H33: =SUM(H31:H32) -> 11556 | I33: =SUM(I31:I32) -> 13580 | J33: =SUM(J31:J32) -> 16097 | K33: =SUM(K31:K32) -> 19748
B35: Invested Capital | G35: =G33+G19 -> 13858 | H35: =H33+H19 -> 17285 | I35: =I33+I19 -> 20064 | J35: =J33+J19 -> 22479 | K35: =K33+K19 -> 26116
B36: EBIT | G36: =HistoricalFS!H18-HistoricalFS!H24 -> 4249.23 | H36: =HistoricalFS!I18-HistoricalFS!I24 -> 6637.19 | I36: =HistoricalFS!J18-HistoricalFS!J24 -> 6021.28 | J36: =HistoricalFS!K18-HistoricalFS!K24 -> 6004.38 | K36: =HistoricalFS!L18-HistoricalFS!L24 -> 5389.87
B38: ROIC | G38: =G36/G35 -> 0.3066265 | H38: =H36/H35 -> 0.38398554 | I38: =I36/I35 -> 0.30010367 | J38: =J36/J35 -> 0.26711064 | K38: =K36/K35 -> 0.20638191
B41: Calculation of Reinvestment Rate | G41: =G4 -> 44256 | H41: =H4 -> 44621 | I41: =I4 -> 44986 | J41: =J4 -> 45352 | K41: =K4 -> 45717
B43: Net Capex | G43: =SUM(HistoricalFS!H82:H83) -> -1681 | H43: =SUM(HistoricalFS!I82:I83) -> -2216 | I43: =SUM(HistoricalFS!J82:J83) -> -3424 | J43: =SUM(HistoricalFS!K82:K83) -> -4187 | K43: =SUM(HistoricalFS!L82:L83) -> -3975
B44: Change in Working Capital | H44: =H19-G19 -> 2795 | I44: =I19-H19 -> 755 | J44: =J19-I19 -> -102 | K44: =K19-J19 -> -14
B46: EBIT | G46: =G36 -> 4249.23 | H46: =H36 -> 6637.19 | I46: =I36 -> 6021.28 | J46: =J36 -> 6004.38 | K46: =K36 -> 5389.87
B47: Marginal Tax Rate | G47: 0.25 | H47: 0.25 | I47: 0.25 | J47: 0.25 | K47: 0.25
B48: EBIT(1-T) | G48: =G46*(1-G47) -> 3186.9225 | H48: =H46*(1-H47) -> 4977.8925 | I48: =I46*(1-I47) -> 4515.96 | J48: =J46*(1-J47) -> 4503.285 | K48: =K46*(1-K47) -> 4042.4025
B50: Reinvestment | H50: =SUM(H43:H44) -> 579 | I50: =SUM(I43:I44) -> -2669 | J50: =SUM(J43:J44) -> -4289 | K50: =SUM(K43:K44) -> -3989
B52: Reinvestment Rate | H52: =H50/H48 -> 0.11631428 | I52: =I50/I48 -> -0.59101498 | J52: =J50/J48 -> -0.95241585 | K52: =K50/K48 -> -0.98678942
J54: 4 Year Average | K54: =AVERAGE(H52:K52) -> -0.60347649
J55: 4 Year Median | K55: =MEDIAN(H52:K52) -> -0.77171541
...

Sheet DCF
B3: ="DCF Valuation and Sensitivity Analysis"&" - "&'Data Sheet'!B1 -> DCF Valuation and Sensitivity Analysis - ASIAN PAINTS LTD
B4: Amount in crores | F4: 0 | G4: 0.5 | H4: 1.5 | I4: 2.5 | J4: 3.5 | K4: 4.5
B5: Calculation of PV of FCFF | F5: ='Intrinsic Growth'!K4 -> 45717 | G5: =F5+365 -> 46082 | H5: =G5+365 -> 46447 | I5: =H5+365 -> 46812 | J5: =I5+365 -> 47177 | K5: =J5+365 -> 47542
B7: EBIT | F7: ='Intrinsic Growth'!K36 -> 5389.87 | G7: =F7*(1+$E$21) -> 6508.268 | H7: =G7*(1+$E$21) -> 7858.7336 | I7: =H7*(1+$E$21) -> 9489.4209 | J7: =I7*(1+$E$21) -> 11458.476 | K7: =J7*(1+$E$21) -> 13836.109
B9: Tax Rate | F9: 0.25 | G9: =F9 -> 0.25 | H9: =G9 -> 0.25 | I9: =H9 -> 0.25 | J9: =I9 -> 0.25 | K9: =J9 -> 0.25
B11: EBIT (1-T) | F11: =F7*(1-F9) -> 4042.4025 | G11: =G7*(1-G9) -> 4881.201 | H11: =H7*(1-H9) -> 5894.0502 | I11: =I7*(1-I9) -> 7117.0657 | J11: =J7*(1-J9) -> 8593.8568 | K11: =K7*(1-K9) -> 10377.082
B13: Less: Reinvestment Rate | F13: ='Intrinsic Growth'!K55 -> -0.77171541 | G13: =F13 -> -0.77171541 | H13: =G13 -> -0.77171541 | I13: =H13 -> -0.77171541 | J13: =I13 -> -0.77171541 | K13: =J13 -> -0.77171541
B15: Free Cash Flow to Firm | F15: =F11*(1-F13) -> 7161.9868 | G15: =G11*(1-G13) -> 8648.0991 | H15: =H11*(1-H13) -> 10442.58 | I15: =I11*(1-I13) -> 12609.415 | J15: =J11*(1-J13) -> 15225.869 | K15: =K11*(1-K13) -> 18385.236
B17: Discounting Factor | F17: =1/(1+$E$28)^F4 -> 1 | G17: =1/(1+$E$28)^G4 -> 0.93255652 | H17: =1/(1+$E$28)^H4 -> 0.81100865 | I17: =1/(1+$E$28)^I4 -> 0.70530312 | J17: =1/(1+$E$28)^J4 -> 0.61337508 | K17: =1/(1+$E$28)^K4 -> 0.53342879
B19: PV of FCFF | F19: =F17*F15 -> 7161.9868 | G19: =G17*G15 -> 8064.8412 | H19: =H17*H15 -> 8469.0224 | I19: =I17*I15 -> 8893.4597 | J19: =J17*J15 -> 9339.1684 | K19: =K17*K15 -> 9807.2143
B21: Expected Growth | E21: 0.2075
B22: Terminal Growth | E22: 0.064
B25: Calculation of Terminal Value | G25: Sensitivity Analysis
G26: =E44 -> 1977.3551 | H26: 0.13 | I26: 0.14 | J26: =E28 -> 0.14987247 | K26: 0.16 | L26: 0.17
B27: FCFF (n+1) | E27: =K15*(1+E21) -> 22200.173 | G27: 0.04 | H27: 2045.0843 | I27: 1833.5683 | J27: 1833.5683 | K27: 1517.9739 | L27: 1397.3163
B28: WACC | E28: =WACC!J44 -> 0.14987247 | G28: 0.05 | H28: 2230.6564 | I28: 1976.2551 | J28: 1976.2551 | K28: 1607.9368 | L28: 1470.5545
B29: Terminal Growth Rate | E29: =E22 -> 0.064 | G29: =E29 -> 0.064 | H29: 2230.6564 | I29: 1976.2551 | J29: 1976.2551 | K29: 1607.9368 | L29: 1470.5545
G30: 0.07 | H30: 2787.3728 | I30: 2383.9318 | J30: 2383.9318 | K30: 1847.8378 | L30: 1660.9736
B31: Terminal Value | E31: =E27/(E28-E29) -> 258524.9 | G31: 0.08 | H31: 3232.7458 | I31: 2689.6893 | J31: 2689.6893 | K31: 2012.7697 | L31: 1787.9197
B34: Calculation of Enterprise Value
B36: PV of FCFF | E36: =SUM(F19:K19) -> 51735.693
B37: PV of Terminal Value | E37: =E31*K17 -> 137904.63
B38: Value of Operating Asset | E38: =SUM(E36:E37) -> 189640.32
B40: Add: Cash | E40: =HistoricalFS!L62 -> 781.98
B41: Less: Debt | E41: =SUM('Raw FS'!L7:L8) -> 864
B42: Value of Equity | E42: =(E38+E40)-E41 -> 189558.3
B43: No. of Shares | E43: ='Data Sheet'!B6 -> 95.864573
B44: Value per Share | E44: =E42/E43 -> 1977.3551

Sheet Comps_Val
B2: Amount in crores
B3: Comparable Company Valuation
D5: Market Data | K5: Financials | O5: Valuation
B6: Company | C6: Ticker | D6: Share Price | E6: Shares Outstanding | F6: Equity Value | G6: Net Debt | H6: Enterprise Value | K6: Revenue | L6: EBITDA | M6: Net Income | O6: EV/Revenue | P6: EV/EBITDA | Q6: P/E
B8: =Data!C3 -> Asian Paints | D8: =Data!D3 -> 2518.6 | E8: =Data!E3 -> 95.92 | F8: =E8*D8 -> 241584.11 | G8: =Data!I3 -> 1508.31 | H8: =+F8+G8 -> 243092.42 | K8: =Data!K3 -> 33874.44 | L8: =Data!L3 -> 6686.91 | M8: =Data!O3 -> 3639.97 | O8: =$H8/K8 -> 7.1762787 | P8: =$H8/L8 -> 36.353476 | Q8: =F8/M8 -> 66.369809
B9: =Data!C4 -> Berger Paints | D9: =Data!D4 -> 533 | E9: =Data!E4 -> 116.59 | F9: =E9*D9 -> 62142.47 | G9: =Data!I4 -> 169.79 | H9: =+F9+G9 -> 62312.26 | K9: =Data!K4 -> 11654.46 | L9: =Data!L4 -> 1985.61 | M9: =Data!O4 -> 1143.82 | O9: =$H9/K9 -> 5.346645 | P9: =$H9/L9 -> 31.381923 | Q9: =F9/M9 -> 54.328889
B10: =Data!C5 -> Kansai Nerolac | D10: =Data!D5 -> 239.99 | E10: =Data!E5 -> 80.85 | F10: =E10*D10 -> 19403.192 | G10: =Data!I5 -> 6.33 | H10: =+F10+G10 -> 19409.522 | K10: =Data!K5 -> 7851.94 | L10: =Data!L5 -> 1073.79 | M10: =Data!O5 -> 1100.05 | O10: =$H10/K10 -> 2.4719396 | P10: =$H10/L10 -> 18.075715 | Q10: =F10/M10 -> 17.638463
B11: =Data!C6 -> Akzo Nobel | D11: =Data!D6 -> 3410.6 | E11: =Data!E6 -> 4.55 | F11: =E11*D11 -> 15518.23 | G11: =Data!I6 -> -237.4 | H11: =+F11+G11 -> 15280.83 | K11: =Data!K6 -> 4050 | L11: =Data!L6 -> 633.7 | M11: =Data!O6 -> 405 | O11: =$H11/K11 -> 3.7730444 | P11: =$H11/L11 -> 24.113666 | Q11: =F11/M11 -> 38.316617
B12: =Data!C7 -> Indigo Paints | D12: =Data!D7 -> 1099.7 | E12: =Data!E7 -> 4.76 | F12: =E12*D12 -> 5234.572 | G12: =Data!I7 -> -17.4 | H12: =+F12+G12 -> 5217.172 | K12: =Data!K7 -> 1278.1 | L12: =Data!L7 -> 248.54 | M12: =Data!O7 -> 143.84 | O12: =$H12/K12 -> 4.0819748 | P12: =$H12/L12 -> 20.991277 | Q12: =F12/M12 -> 36.39163
B13: =Data!C8 -> Sirca Paints | D13: =Data!D8 -> 462.75 | E13: =Data!E8 -> 5.48 | F13: =E13*D13 -> 2535.87 | G13: =Data!I8 -> -54.16 | H13: =+F13+G13 -> 2481.71 | K13: =Data!K8 -> 409.37 | L13: =Data!L8 -> 79.9 | M13: =Data!O8 -> 53.11 | O13: =$H13/K13 -> 6.0622664 | P13: =$H13/L13 -> 31.0602 | Q13: =F13/M13 -> 47.747505
B14: =Data!C9 -> Shalimar Paints | D14: =Data!D9 -> 71.73 | E14: =Data!E9 -> 8.37 | F14: =E14*D14 -> 600.3801 | G14: =Data!I9 -> 118.39 | H14: =+F14+G14 -> 718.7701 | K14: =Data!K9 -> 624.19 | L14: =Data!L9 -> -32.52 | M14: =Data!O9 -> -69.79 | O14: =$H14/K14 -> 1.1515245 | P14: =$H14/L14 -> -22.102402 | Q14: =F14/M14 -> -8.6026666
B15: =Data!C10 -> Kamdhenu Venture | D15: =Data!D10 -> 10.21 | E15: =Data!E10 -> 31.44 | F15: =E15*D15 -> 321.0024 | G15: =Data!I10 -> 21.08 | H15: =+F15+G15 -> 342.0824 | K15: =Data!K10 -> 261.89 | L15: =Data!L10 -> 16.77 | M15: =Data!O10 -> 5.94 | O15: =$H15/K15 -> 1.3062064 | P15: =$H15/L15 -> 20.398473 | Q15: =F15/M15 -> 54.040808
B16: =Data!C11 -> Siddhika Coatins | D16: =Data!D11 -> 190 | E16: =Data!E11 -> 0.62 | F16: =E16*D16 -> 117.8 | G16: =Data!I11 -> -5.76 | H16: =+F16+G16 -> 112.04 | K16: =Data!K11 -> 48.01 | L16: =Data!L11 -> 10.44 | M16: =Data!O11 -> 8.03 | O16: =$H16/K16 -> 2.3336805 | P16: =$H16/L16 -> 10.731801 | Q16: =F16/M16 -> 14.669988
B17: =Data!C12 -> Retina Paints | D17: =Data!D12 -> 76.5 | E17: =Data!E12 -> 1.53 | F17: =E17*D17 -> 117.045 | G17: =Data!I12 -> 7.76 | H17: =+F17+G17 -> 124.805 | K17: =Data!K12 -> 11.66 | L17: =Data!L12 -> 2.02 | M17: =Data!O12 -> 0.74 | O17: =$H17/K17 -> 10.703688 | P17: =$H17/L17 -> 61.784653 | Q17: =F17/M17 -> 158.16892
B19: High | O19: =MAX(O8:O17) -> 10.703688 | P19: =MAX(P8:P17) -> 61.784653 | Q19: =MAX(Q8:Q17) -> 158.16892
B20: 75th Percentile | O20: =QUARTILE(O8:O17,3) -> 5.8833611 | P20: =QUARTILE(P8:P17,3) -> 31.301492 | Q20: =QUARTILE(Q8:Q17,3) -> 54.256869
B21: Average | O21: =AVERAGE(O8:O17) -> 4.4407248 | P21: =AVERAGE(P8:P17) -> 23.278878 | Q21: =AVERAGE(Q8:Q17) -> 47.906996
B22: Median | O22: =MEDIAN(O8:O17) -> 3.9275096 | P22: =MEDIAN(P8:P17) -> 22.552471 | Q22: =MEDIAN(Q8:Q17) -> 43.032061
B23: 25th Percentile | O23: =QUARTILE(O8:O17,1) -> 2.3682453 | P23: =QUARTILE(P8:P17,1) -> 18.656404 | Q23: =QUARTILE(Q8:Q17,1) -> 22.326755
B24: Low | O24: =MIN(O8:O17) -> 1.1515245 | P24: =MIN(P8:P17) -> -22.102402 | Q24: =MIN(Q8:Q17) -> -8.6026666
B26: Asian Paints Comparable Valuation | O26: EV/Revenue | P26: EV/EBITDA | Q26: P/E
B28: Implied Enterprise Value | O28: =O$22*K8 -> 133042.19 | P28: =P$22*L8 -> 150806.35 | Q28: =+Q30+Q29 -> 158143.72
B29: Net Debt | O29: =$G$8 -> 1508.31 | P29: =$G$8 -> 1508.31 | Q29: =$G$8 -> 1508.31
B30: Implied Market Value | O30: =O28-O29 -> 131533.88 | P30: =P28-P29 -> 149298.04 | Q30: =Q22*M8 -> 156635.41
B31: Shares Outstanding | O31: =$E$8 -> 95.92 | P31: =$E$8 -> 95.92 | Q31: =$E$8 -> 95.92
B33: Implied Value per Share | O33: =O30/O31 -> 1371.2873 | P33: =P30/P31 -> 1556.485 | Q33: =Q30/Q31 -> 1632.9797
B35: Source: Screener.in
O36: =IF(O33>$D$8,"Undervalued","Overvalued") -> Overvalued | P36: =IF(P33>$D$8,"Undervalued","Overvalued") -> Overvalued | Q36: =IF(Q33>$D$8,"Undervalued","Overvalued") -> Overvalued

Sheet Football Field Analysis
B4: ="Football Field Analysis"&" - "&'Data Sheet'!B1 -> Football Field Analysis - ASIAN PAINTS LTD
B23: Football Field Analysis - Data
C24: Open Low | D24: Low | E24: Open High | F24: High
B25: Comps | C25: =Comps_Val!O33 -> 1371.2873 | D25: =C25 -> 1371.2873 | E25: =Comps_Val!Q33 -> 1632.9797 | F25: =E25 -> 1632.9797
B26: DCF Bear | C26: 1396.512 | D26: 1396.512 | E26: 1786.8905 | F26: 1786.8905
B27: DCF Base | C27: 1832.5129 | D27: 1832.5129 | E27: 2688.141 | F27: 2688.141
B28: DCF Bull | C28: 2043.9071 | D28: 2043.9071 | E28: 3230.885 | F28: 3230.885
B29: 52W H/L | C29: 2124.75 | D29: 2124.75 | E29: 3394.9 | F29: 3394.9

Sheet Ratio Analysis
B2: ="Ratio Analysis - "&'Data Sheet'!B1 -> Ratio Analysis - ASIAN PAINTS LTD
B3: Years | C3: ='Data Sheet'!B16 -> 42460 | D3: ='Data Sheet'!C16 -> 42825 | E3: ='Data Sheet'!D16 -> 43190 | F3: ='Data Sheet'!E16 -> 43555 | G3: ='Data Sheet'!F16 -> 43921 | H3: ='Data Sheet'!G16 -> 44286 | I3: ='Data Sheet'!H16 -> 44651 | J3: ='Data Sheet'!I16 -> 45016 | ... L3: ='Data Sheet'!K16 -> 45747 | M3: Trend | N3: Mean | O3: Median
B5: SalesGrowth | D5: =IFERROR(HistoricalFS!D7,0) -> 0.055390152 | E5: =IFERROR(HistoricalFS!E7,0) -> 0.11702039 | F5: =IFERROR(HistoricalFS!F7,0) -> 0.14357472 | G5: =IFERROR(HistoricalFS!G7,0) -> 0.050473671 | H5: =IFERROR(HistoricalFS!H7,0) -> 0.074292288 | I5: =IFERROR(HistoricalFS!I7,0) -> 0.34028285 | J5: =IFERROR(HistoricalFS!J7,0) -> 0.18512278 | K5: =IFERROR(HistoricalFS!K7,0) -> 0.029173127 | L5: =IFERROR(HistoricalFS!L7,0) -> -0.044770308 | N5: =IFERROR(AVERAGE(D5:L5),0) -> 0.10561774 | O5: =IFERROR(MEDIAN(C5:L5),0) -> 0.074292288
B6: EBITDA Growth | D6: =IFERROR(HistoricalFS!D18/HistoricalFS!C18-1,0) -> 0.74131483 | E6: =IFERROR(HistoricalFS!E18/HistoricalFS!D18-1,0) -> -0.27924492 | F6: =IFERROR(HistoricalFS!F18/HistoricalFS!E18-1,0) -> 0.49035363 | G6: =IFERROR(HistoricalFS!G18/HistoricalFS!F18-1,0) -> 0.065187316 | H6: =IFERROR(HistoricalFS!H18/HistoricalFS!G18-1,0) -> 0.087458361 | I6: =IFERROR(HistoricalFS!I18/HistoricalFS!H18-1,0) -> 0.47873227 | J6: =IFERROR(HistoricalFS!J18/HistoricalFS!I18-1,0) -> -0.077043825 | K6: =IFERROR(HistoricalFS!K18/HistoricalFS!J18-1,0) -> -0.0031863707 | L6: =IFERROR(HistoricalFS!L18/HistoricalFS!K18-1,0) -> -0.064335067 | N6: =IFERROR(AVERAGE(D6:L6),0) -> 0.15991514 | O6: =IFERROR(MEDIAN(C6:L6),0) -> 0.065187316
B7: EBIT Growth | D7: =IFERROR(HistoricalFS!D27/HistoricalFS!C27-1,0) -> 0.83776601 | E7: =IFERROR(HistoricalFS!E27/HistoricalFS!D27-1,0) -> -0.31559676 | F7: =IFERROR(HistoricalFS!F27/HistoricalFS!E27-1,0) -> 0.43730067 | G7: =IFERROR(HistoricalFS!G27/HistoricalFS!F27-1,0) -> 0.036873592 | H7: =IFERROR(HistoricalFS!H27/HistoricalFS!G27-1,0) -> 0.1080167 | I7: =IFERROR(HistoricalFS!I27/HistoricalFS!H27-1,0) -> 0.57345103 | J7: =IFERROR(HistoricalFS!J27/HistoricalFS!I27-1,0) -> -0.10164665 | K7: =IFERROR(HistoricalFS!K27/HistoricalFS!J27-1,0) -> -0.013207801 | L7: =IFERROR(HistoricalFS!L27/HistoricalFS!K27-1,0) -> -0.10973219 | N7: =IFERROR(AVERAGE(D7:L7),0) -> 0.1614694 | O7: =IFERROR(MEDIAN(C7:L7),0) -> 0.036873592
B8: Net Profit Growth | D8: =IFERROR(HistoricalFS!D33/HistoricalFS!C33-1,0) -> 1.3637141 | E8: =IFERROR(HistoricalFS!E33/HistoricalFS!D33-1,0) -> -0.46012685 | F8: =IFERROR(HistoricalFS!F33/HistoricalFS!E33-1,0) -> 0.70686935 | G8: =IFERROR(HistoricalFS!G33/HistoricalFS!F33-1,0) -> 0.14941744 | H8: =IFERROR(HistoricalFS!H33/HistoricalFS!G33-1,0) -> 0.056104699 | I8: =IFERROR(HistoricalFS!I33/HistoricalFS!H33-1,0) -> 0.7774085 | J8: =IFERROR(HistoricalFS!J33/HistoricalFS!I33-1,0) -> -0.1940734 | K8: =IFERROR(HistoricalFS!K33/HistoricalFS!J33-1,0) -> -0.085368886 | L8: =IFERROR(HistoricalFS!L33/HistoricalFS!K33-1,0) -> -0.059773567 | N8: =IFERROR(AVERAGE(D8:L8),0) -> 0.25046349 | O8: =IFERROR(MEDIAN(C8:L8),0) -> 0.056104699
B9: Dividend Growth | D9: =IFERROR(HistoricalFS!D41/HistoricalFS!C41-1,0) -> 0.37333889 | E9: =IFERROR(HistoricalFS!E41/HistoricalFS!D41-1,0) -> -0.15534727 | F9: =IFERROR(HistoricalFS!F41/HistoricalFS!E41-1,0) -> 0.20690234 | G9: =IFERROR(HistoricalFS!G41/HistoricalFS!F41-1,0) -> 0.14285714 | H9: =IFERROR(HistoricalFS!H41/HistoricalFS!G41-1,0) -> 0.48749826 | I9: =IFERROR(HistoricalFS!I41/HistoricalFS!H41-1,0) -> 0.072831553 | J9: =IFERROR(HistoricalFS!J41/HistoricalFS!I41-1,0) -> 0.33942522 | K9: =IFERROR(HistoricalFS!K41/HistoricalFS!J41-1,0) -> 0.29824618 | L9: =IFERROR(HistoricalFS!L41/HistoricalFS!K41-1,0) -> -0.25525494 | N9: =IFERROR(AVERAGE(D9:L9),0) -> 0.16783304 | O9: =IFERROR(MEDIAN(C9:L9),0) -> 0.20690234
B11: Gross Margin | C11: =IFERROR(HistoricalFS!C13,0) -> 0.3124404 | D11: =IFERROR(HistoricalFS!D13,0) -> 0.42401635 | E11: =IFERROR(HistoricalFS!E13,0) -> 0.31775709 | F11: =IFERROR(HistoricalFS!F13,0) -> 0.35970859 | G11: =IFERROR(HistoricalFS!G13,0) -> 0.37264048 | H11: =IFERROR(HistoricalFS!H13,0) -> 0.36211929 | I11: =IFERROR(HistoricalFS!I13,0) -> 0.38351062 | J11: =IFERROR(HistoricalFS!J13,0) -> 0.32884354 | ... L11: =IFERROR(HistoricalFS!L13,0) -> 0.34136966 | N11: =IFERROR(AVERAGE(C11:L11),0) -> 0.35336422 | O11: =IFERROR(MEDIAN(C11:L11),0) -> 0.35053912
B12: EBITDA Margin | C12: =IFERROR(HistoricalFS!C19,0) -> 0.16300891 | D12: =IFERROR(HistoricalFS!D19,0) -> 0.26895251 | E12: =IFERROR(HistoricalFS!E19,0) -> 0.17354105 | F12: =IFERROR(HistoricalFS!F19,0) -> 0.22616583 | G12: =IFERROR(HistoricalFS!G19,0) -> 0.22933366 | H12: =IFERROR(HistoricalFS!H19,0) -> 0.23214428 | I12: =IFERROR(HistoricalFS!I19,0) -> 0.25612447 | J12: =IFERROR(HistoricalFS!J19,0) -> 0.19946597 | ... L12: =IFERROR(HistoricalFS!L19,0) -> 0.18923736 | N12: =IFERROR(AVERAGE(C12:L12),0) -> 0.21311684 | O12: =IFERROR(MEDIAN(C12:L12),0) -> 0.2128159
B13: EBIT Margin | C13: =IFERROR((HistoricalFS!C18-HistoricalFS!C24)/HistoricalFS!C6,0) -> 0.14369908 | D13: =IFERROR((HistoricalFS!D18-HistoricalFS!D24)/HistoricalFS!D6,0) -> 0.24672503 | E13: =IFERROR((HistoricalFS!E18-HistoricalFS!E24)/HistoricalFS!E6,0) -> 0.15211581 | F13: =IFERROR((HistoricalFS!F18-HistoricalFS!F24)/HistoricalFS!F6,0) -> 0.19383029 | G13: =IFERROR((HistoricalFS!G18-HistoricalFS!G24)/HistoricalFS!G6,0) -> 0.19071656 | H13: =IFERROR((HistoricalFS!H18-HistoricalFS!H24)/HistoricalFS!H6,0) -> 0.1957017 | I13: =IFERROR((HistoricalFS!I18-HistoricalFS!I24)/HistoricalFS!I6,0) -> 0.2280721 | J13: =IFERROR((HistoricalFS!J18-HistoricalFS!J24)/HistoricalFS!J6,0) -> 0.1745876 | ... L13: =IFERROR((HistoricalFS!L18-HistoricalFS!L24)/HistoricalFS!L6,0) -> 0.15896686 | N13: =IFERROR(AVERAGE(C13:L13),0) -> 0.18535776 | O13: =IFERROR(MEDIAN(C13:L13),0) -> 0.18265208
B14: EBT Margin | C14: =IFERROR(HistoricalFS!C28,0) -> 0.14026566 | D14: =IFERROR(HistoricalFS!D28,0) -> 0.24424661 | E14: =IFERROR(HistoricalFS!E28,0) -> 0.14965096 | F14: =IFERROR(HistoricalFS!F28,0) -> 0.18808865 | G14: =IFERROR(HistoricalFS!G28,0) -> 0.18565353 | H14: =IFERROR(HistoricalFS!H28,0) -> 0.19148161 | I14: =IFERROR(HistoricalFS!I28,0) -> 0.22479355 | J14: =IFERROR(HistoricalFS!J28,0) -> 0.17039925 | ... L14: =IFERROR(HistoricalFS!L28,0) -> 0.15227122 | N14: =IFERROR(AVERAGE(C14:L14),0) -> 0.18102333 | O14: =IFERROR(MEDIAN(C14:L14),0) -> 0.17802639
B15: Net Profit Margin | C15: =IFERROR(HistoricalFS!C34,0) -> 0.081092444 | D15: =IFERROR(HistoricalFS!D34,0) -> 0.18161943 | E15: =IFERROR(HistoricalFS!E34,0) -> 0.087779465 | F15: =IFERROR(HistoricalFS!F34,0) -> 0.13101731 | G15: =IFERROR(HistoricalFS!G34,0) -> 0.14335778 | H15: =IFERROR(HistoricalFS!H34,0) -> 0.14093076 | I15: =IFERROR(HistoricalFS!I34,0) -> 0.18689453 | J15: =IFERROR(HistoricalFS!J34,0) -> 0.12709508 | ... L15: =IFERROR(HistoricalFS!L34,0) -> 0.11117596 | N15: =IFERROR(AVERAGE(C15:L15),0) -> 0.13039128 | O15: =IFERROR(MEDIAN(C15:L15),0) -> 0.12905619
B17: SalesExpenses%Sales | C17: =IFERROR(HistoricalFS!C16,0) -> 0.14943149 | D17: =IFERROR(HistoricalFS!D16,0) -> 0.15506384 | E17: =IFERROR(HistoricalFS!E16,0) -> 0.14421604 | F17: =IFERROR(HistoricalFS!F16,0) -> 0.13354276 | G17: =IFERROR(HistoricalFS!G16,0) -> 0.14330682 | H17: =IFERROR(HistoricalFS!H16,0) -> 0.12997501 | I17: =IFERROR(HistoricalFS!I16,0) -> 0.12738615 | J17: =IFERROR(HistoricalFS!J16,0) -> 0.12937757 | ... L17: =IFERROR(HistoricalFS!L16,0) -> 0.1521323 | N17: =IFERROR(AVERAGE(C17:L17),0) -> 0.14024739 | O17: =IFERROR(MEDIAN(C17:L17),0) -> 0.14067436
B18: Depreciation%Sales | C18: =IFERROR(HistoricalFS!C25,0) -> 0.019309827 | D18: =IFERROR(HistoricalFS!D25,0) -> 0.022227475 | E18: =IFERROR(HistoricalFS!E25,0) -> 0.021425239 | F18: =IFERROR(HistoricalFS!F25,0) -> 0.03233554 | G18: =IFERROR(HistoricalFS!G25,0) -> 0.038617107 | H18: =IFERROR(HistoricalFS!H25,0) -> 0.036442576 | I18: =IFERROR(HistoricalFS!I25,0) -> 0.028052374 | J18: =IFERROR(HistoricalFS!J25,0) -> 0.024878373 | ... L18: =IFERROR(HistoricalFS!L25,0) -> 0.030270498 | N18: =IFERROR(AVERAGE(C18:L18),0) -> 0.027759074 | O18: =IFERROR(MEDIAN(C18:L18),0) -> 0.026465374
B19: OperatingIncome%Sales | C19: =C13 -> 0.14369908 | D19: =D13 -> 0.24672503 | E19: =E13 -> 0.15211581 | F19: =F13 -> 0.19383029 | G19: =G13 -> 0.19071656 | H19: =H13 -> 0.1957017 | I19: =I13 -> 0.2280721 | J19: =J13 -> 0.1745876 | ... L19: =L13 -> 0.15896686 | N19: =IFERROR(AVERAGE(C19:L19),0) -> 0.18535776 | O19: =IFERROR(MEDIAN(C19:L19),0) -> 0.18265208
